Иногда что-то идёт не так как мы хотим

Например, функция `malloc` возвращает `T*` или `nullptr` и мы хотим знать, что вернулось

Функция деления (может быть на 0)

```cpp
#include <exception>

int divide(int a, int b) {
	if (b == 0) {
		throw std::logic_error("Divide by zero!")
	}
	return a / b;
}
```

Как обработать исключение? С помощью `try-catch` блока!

```cpp
try {
	divide (1, 0);
} catch (std::logic_error& err) {
	std::cout << err.what() << '\n';
}
```


`std::terminate` - стандартная функция, которая вызывается RE если исключение произошло и не брошено

потом вызывается функция `std::abort` - убийство

**Всего 3 оператора их бросают**

`new`, `throw` и `dynamic_cast`

Достаточно неочевидный момент:
```cpp
std::vector<int> v;
try {
	v[1'000'000] = 1;
} catch (...) {
	std::cout << "Caught!\n";
}
```


ничего не изменится, потому что вылетает SE - **ЭТО НЕ EXCEPTION**

и деление на 0 - **это не exception**, это exception, но другого уровня - это ошибка уровня **процессора**

se, floating point exception, abort - это RE

если мы падаем из-за плюсового exception, то у нас кидается процессорный exception - `std::abort`

`std::logic_error` - виноват пользователь

`std::runtime_error` - просто чет не так пошло

что приводит к **SE**? **nullptr dereference, array out of bounds, stack overflow**

FPE? - делить на 0

Aborted? - pure virtual function call, uncaught exception, false assertion, std::abort, std::termiate

если есть много кэтчей, то выбирается ТОЛЬКО подходящий

Все исключения наследованы от `std::exception` и там в свою очередь тоже идёт подразделение - это и есть иерархия.